{
 "cells": [
  {
   "cell_type": "code",
   "execution_count": 1,
   "id": "cf3c8c24",
   "metadata": {},
   "outputs": [],
   "source": [
    "import pandas as pd\n",
    "import tensorflow as tf\n",
    "from tensorflow import keras\n",
    "from keras import Sequential\n",
    "import matplotlib.pyplot as plt\n",
    "import os"
   ]
  },
  {
   "cell_type": "code",
   "execution_count": 4,
   "id": "7fb7a272",
   "metadata": {},
   "outputs": [],
   "source": [
    "model = keras.models.Sequential([\n",
    "keras.layers.Flatten(input_shape=[28,28]),\n",
    "keras.layers.Dense(300, activation = \"relu\", kernel_initializer = \"he_normal\"),\n",
    "keras.layers.Dense(100, activation = \"relu\", kernel_regularizer = keras.regularizers.l2(0.01)),\n",
    "keras.layers.Dropout(rate=0.2),\n",
    "keras.layers.Dense(10, activation = \"softmax\")])"
   ]
  },
  {
   "cell_type": "code",
   "execution_count": 6,
   "id": "bb68651a",
   "metadata": {},
   "outputs": [],
   "source": [
    "model.compile(loss = \"sparse_categorical_crossentropy\", optimizer = \"sgd\", metrics = [\"accuracy\"])\n",
    "\n",
    "opt = keras.optimizers.Adam(learning_rate = 0.01)\n",
    "model.compile(loss =\"categorical_crossentropy\", optimizer = opt)"
   ]
  },
  {
   "cell_type": "code",
   "execution_count": 13,
   "id": "27b15c17",
   "metadata": {},
   "outputs": [
    {
     "name": "stdout",
     "output_type": "stream",
     "text": [
      "Epoch 1/30\n"
     ]
    },
    {
     "ename": "ValueError",
     "evalue": "in user code:\n\n    File \"e:\\new folder (2)\\lib\\site-packages\\keras\\engine\\training.py\", line 1160, in train_function  *\n        return step_function(self, iterator)\n    File \"e:\\new folder (2)\\lib\\site-packages\\keras\\engine\\training.py\", line 1146, in step_function  **\n        outputs = model.distribute_strategy.run(run_step, args=(data,))\n    File \"e:\\new folder (2)\\lib\\site-packages\\keras\\engine\\training.py\", line 1135, in run_step  **\n        outputs = model.train_step(data)\n    File \"e:\\new folder (2)\\lib\\site-packages\\keras\\engine\\training.py\", line 994, in train_step\n        loss = self.compute_loss(x, y, y_pred, sample_weight)\n    File \"e:\\new folder (2)\\lib\\site-packages\\keras\\engine\\training.py\", line 1052, in compute_loss\n        return self.compiled_loss(\n    File \"e:\\new folder (2)\\lib\\site-packages\\keras\\engine\\compile_utils.py\", line 265, in __call__\n        loss_value = loss_obj(y_t, y_p, sample_weight=sw)\n    File \"e:\\new folder (2)\\lib\\site-packages\\keras\\losses.py\", line 152, in __call__\n        losses = call_fn(y_true, y_pred)\n    File \"e:\\new folder (2)\\lib\\site-packages\\keras\\losses.py\", line 272, in call  **\n        return ag_fn(y_true, y_pred, **self._fn_kwargs)\n    File \"e:\\new folder (2)\\lib\\site-packages\\keras\\losses.py\", line 1990, in categorical_crossentropy\n        return backend.categorical_crossentropy(\n    File \"e:\\new folder (2)\\lib\\site-packages\\keras\\backend.py\", line 5529, in categorical_crossentropy\n        target.shape.assert_is_compatible_with(output.shape)\n\n    ValueError: Shapes (16, 1) and (16, 10) are incompatible\n",
     "output_type": "error",
     "traceback": [
      "\u001b[1;31m---------------------------------------------------------------------------\u001b[0m",
      "\u001b[1;31mValueError\u001b[0m                                Traceback (most recent call last)",
      "Input \u001b[1;32mIn [13]\u001b[0m, in \u001b[0;36m<cell line: 1>\u001b[1;34m()\u001b[0m\n\u001b[1;32m----> 1\u001b[0m history \u001b[38;5;241m=\u001b[39m \u001b[43mmodel\u001b[49m\u001b[38;5;241;43m.\u001b[39;49m\u001b[43mfit\u001b[49m\u001b[43m(\u001b[49m\u001b[43mx_train\u001b[49m\u001b[43m,\u001b[49m\u001b[43m \u001b[49m\u001b[43my_train\u001b[49m\u001b[43m,\u001b[49m\u001b[43m \u001b[49m\u001b[43mepochs\u001b[49m\u001b[43m \u001b[49m\u001b[38;5;241;43m=\u001b[39;49m\u001b[43m \u001b[49m\u001b[38;5;241;43m30\u001b[39;49m\u001b[43m,\u001b[49m\u001b[43m \u001b[49m\u001b[43mvalidation_data\u001b[49m\u001b[43m \u001b[49m\u001b[38;5;241;43m=\u001b[39;49m\u001b[43m \u001b[49m\u001b[43m(\u001b[49m\u001b[43mx_valid\u001b[49m\u001b[43m,\u001b[49m\u001b[43m \u001b[49m\u001b[43my_valid\u001b[49m\u001b[43m)\u001b[49m\u001b[43m,\u001b[49m\u001b[43m \u001b[49m\u001b[43mbatch_size\u001b[49m\u001b[43m \u001b[49m\u001b[38;5;241;43m=\u001b[39;49m\u001b[43m \u001b[49m\u001b[38;5;241;43m16\u001b[39;49m\u001b[43m)\u001b[49m\n",
      "File \u001b[1;32me:\\new folder (2)\\lib\\site-packages\\keras\\utils\\traceback_utils.py:70\u001b[0m, in \u001b[0;36mfilter_traceback.<locals>.error_handler\u001b[1;34m(*args, **kwargs)\u001b[0m\n\u001b[0;32m     67\u001b[0m     filtered_tb \u001b[38;5;241m=\u001b[39m _process_traceback_frames(e\u001b[38;5;241m.\u001b[39m__traceback__)\n\u001b[0;32m     68\u001b[0m     \u001b[38;5;66;03m# To get the full stack trace, call:\u001b[39;00m\n\u001b[0;32m     69\u001b[0m     \u001b[38;5;66;03m# `tf.debugging.disable_traceback_filtering()`\u001b[39;00m\n\u001b[1;32m---> 70\u001b[0m     \u001b[38;5;28;01mraise\u001b[39;00m e\u001b[38;5;241m.\u001b[39mwith_traceback(filtered_tb) \u001b[38;5;28;01mfrom\u001b[39;00m \u001b[38;5;28mNone\u001b[39m\n\u001b[0;32m     71\u001b[0m \u001b[38;5;28;01mfinally\u001b[39;00m:\n\u001b[0;32m     72\u001b[0m     \u001b[38;5;28;01mdel\u001b[39;00m filtered_tb\n",
      "File \u001b[1;32m~\\AppData\\Local\\Temp\\__autograph_generated_fileje59955a.py:15\u001b[0m, in \u001b[0;36mouter_factory.<locals>.inner_factory.<locals>.tf__train_function\u001b[1;34m(iterator)\u001b[0m\n\u001b[0;32m     13\u001b[0m \u001b[38;5;28;01mtry\u001b[39;00m:\n\u001b[0;32m     14\u001b[0m     do_return \u001b[38;5;241m=\u001b[39m \u001b[38;5;28;01mTrue\u001b[39;00m\n\u001b[1;32m---> 15\u001b[0m     retval_ \u001b[38;5;241m=\u001b[39m ag__\u001b[38;5;241m.\u001b[39mconverted_call(ag__\u001b[38;5;241m.\u001b[39mld(step_function), (ag__\u001b[38;5;241m.\u001b[39mld(\u001b[38;5;28mself\u001b[39m), ag__\u001b[38;5;241m.\u001b[39mld(iterator)), \u001b[38;5;28;01mNone\u001b[39;00m, fscope)\n\u001b[0;32m     16\u001b[0m \u001b[38;5;28;01mexcept\u001b[39;00m:\n\u001b[0;32m     17\u001b[0m     do_return \u001b[38;5;241m=\u001b[39m \u001b[38;5;28;01mFalse\u001b[39;00m\n",
      "\u001b[1;31mValueError\u001b[0m: in user code:\n\n    File \"e:\\new folder (2)\\lib\\site-packages\\keras\\engine\\training.py\", line 1160, in train_function  *\n        return step_function(self, iterator)\n    File \"e:\\new folder (2)\\lib\\site-packages\\keras\\engine\\training.py\", line 1146, in step_function  **\n        outputs = model.distribute_strategy.run(run_step, args=(data,))\n    File \"e:\\new folder (2)\\lib\\site-packages\\keras\\engine\\training.py\", line 1135, in run_step  **\n        outputs = model.train_step(data)\n    File \"e:\\new folder (2)\\lib\\site-packages\\keras\\engine\\training.py\", line 994, in train_step\n        loss = self.compute_loss(x, y, y_pred, sample_weight)\n    File \"e:\\new folder (2)\\lib\\site-packages\\keras\\engine\\training.py\", line 1052, in compute_loss\n        return self.compiled_loss(\n    File \"e:\\new folder (2)\\lib\\site-packages\\keras\\engine\\compile_utils.py\", line 265, in __call__\n        loss_value = loss_obj(y_t, y_p, sample_weight=sw)\n    File \"e:\\new folder (2)\\lib\\site-packages\\keras\\losses.py\", line 152, in __call__\n        losses = call_fn(y_true, y_pred)\n    File \"e:\\new folder (2)\\lib\\site-packages\\keras\\losses.py\", line 272, in call  **\n        return ag_fn(y_true, y_pred, **self._fn_kwargs)\n    File \"e:\\new folder (2)\\lib\\site-packages\\keras\\losses.py\", line 1990, in categorical_crossentropy\n        return backend.categorical_crossentropy(\n    File \"e:\\new folder (2)\\lib\\site-packages\\keras\\backend.py\", line 5529, in categorical_crossentropy\n        target.shape.assert_is_compatible_with(output.shape)\n\n    ValueError: Shapes (16, 1) and (16, 10) are incompatible\n"
     ]
    }
   ],
   "source": [
    "history = model.fit(x_train, y_train, epochs = 30, validation_data = (x_valid, y_valid), batch_size = 16)"
   ]
  },
  {
   "cell_type": "code",
   "execution_count": 12,
   "id": "88d8a8c8",
   "metadata": {},
   "outputs": [],
   "source": [
    "mnist = keras.datasets.mnist\n",
    "(x_train_full, y_train_full),(x_test, y_test) = mnist.load_data()\n",
    "x_valid, x_train = x_train_full/255, x_train_full\n",
    "y_valid, y_train = y_train_full/255, y_train_full\n",
    "x_test = x_test/255"
   ]
  },
  {
   "cell_type": "code",
   "execution_count": null,
   "id": "efafabbf",
   "metadata": {},
   "outputs": [],
   "source": []
  }
 ],
 "metadata": {
  "kernelspec": {
   "display_name": "Python 3 (ipykernel)",
   "language": "python",
   "name": "python3"
  },
  "language_info": {
   "codemirror_mode": {
    "name": "ipython",
    "version": 3
   },
   "file_extension": ".py",
   "mimetype": "text/x-python",
   "name": "python",
   "nbconvert_exporter": "python",
   "pygments_lexer": "ipython3",
   "version": "3.9.6"
  }
 },
 "nbformat": 4,
 "nbformat_minor": 5
}
